[2025-03-27T07:02:06.516+0000] {taskinstance.py:1165} INFO - Dependencies all met for <TaskInstance: data_ingestion_gcs_dag.local_to_gcs_task1 manual__2025-03-27T06:56:30.206563+00:00 [queued]>
[2025-03-27T07:02:06.530+0000] {taskinstance.py:1165} INFO - Dependencies all met for <TaskInstance: data_ingestion_gcs_dag.local_to_gcs_task1 manual__2025-03-27T06:56:30.206563+00:00 [queued]>
[2025-03-27T07:02:06.531+0000] {taskinstance.py:1362} INFO - 
--------------------------------------------------------------------------------
[2025-03-27T07:02:06.533+0000] {taskinstance.py:1363} INFO - Starting attempt 1 of 2
[2025-03-27T07:02:06.533+0000] {taskinstance.py:1364} INFO - 
--------------------------------------------------------------------------------
[2025-03-27T07:02:06.554+0000] {taskinstance.py:1383} INFO - Executing <Task(PythonOperator): local_to_gcs_task1> on 2025-03-27 06:56:30.206563+00:00
[2025-03-27T07:02:06.564+0000] {standard_task_runner.py:54} INFO - Started process 1186 to run task
[2025-03-27T07:02:06.570+0000] {standard_task_runner.py:82} INFO - Running: ['***', 'tasks', 'run', 'data_ingestion_gcs_dag', 'local_to_gcs_task1', 'manual__2025-03-27T06:56:30.206563+00:00', '--job-id', '15', '--raw', '--subdir', 'DAGS_FOLDER/data_ingestion_gcs_dag.py', '--cfg-path', '/tmp/tmpj8qv48i6']
[2025-03-27T07:02:06.573+0000] {standard_task_runner.py:83} INFO - Job 15: Subtask local_to_gcs_task1
[2025-03-27T07:02:06.574+0000] {dagbag.py:525} INFO - Filling up the DagBag from /opt/***/dags/data_ingestion_gcs_dag.py
[2025-03-27T07:02:06.716+0000] {task_command.py:384} INFO - Running <TaskInstance: data_ingestion_gcs_dag.local_to_gcs_task1 manual__2025-03-27T06:56:30.206563+00:00 [running]> on host af13dacd80a6
[2025-03-27T07:02:06.820+0000] {taskinstance.py:1590} INFO - Exporting the following env vars:
AIRFLOW_CTX_DAG_OWNER=***
AIRFLOW_CTX_DAG_ID=data_ingestion_gcs_dag
AIRFLOW_CTX_TASK_ID=local_to_gcs_task1
AIRFLOW_CTX_EXECUTION_DATE=2025-03-27T06:56:30.206563+00:00
AIRFLOW_CTX_TRY_NUMBER=1
AIRFLOW_CTX_DAG_RUN_ID=manual__2025-03-27T06:56:30.206563+00:00
[2025-03-27T07:02:06.824+0000] {taskinstance.py:1851} ERROR - Task failed with exception
Traceback (most recent call last):
  File "/home/airflow/.local/lib/python3.9/site-packages/airflow/operators/python.py", line 175, in execute
    return_value = self.execute_callable()
  File "/home/airflow/.local/lib/python3.9/site-packages/airflow/operators/python.py", line 193, in execute_callable
    return self.python_callable(*self.op_args, **self.op_kwargs)
  File "/opt/airflow/dags/data_ingestion_gcs_dag.py", line 41, in upload_to_gcs
    client = storage.Client()
  File "/home/airflow/.local/lib/python3.9/site-packages/google/cloud/storage/client.py", line 124, in __init__
    super(Client, self).__init__(
  File "/home/airflow/.local/lib/python3.9/site-packages/google/cloud/client/__init__.py", line 320, in __init__
    _ClientProjectMixin.__init__(self, project=project, credentials=credentials)
  File "/home/airflow/.local/lib/python3.9/site-packages/google/cloud/client/__init__.py", line 268, in __init__
    project = self._determine_default(project)
  File "/home/airflow/.local/lib/python3.9/site-packages/google/cloud/client/__init__.py", line 287, in _determine_default
    return _determine_default_project(project)
  File "/home/airflow/.local/lib/python3.9/site-packages/google/cloud/_helpers/__init__.py", line 152, in _determine_default_project
    _, project = google.auth.default()
  File "/home/airflow/.local/lib/python3.9/site-packages/google/auth/_default.py", line 583, in default
    credentials, project_id = checker()
  File "/home/airflow/.local/lib/python3.9/site-packages/google/auth/_default.py", line 576, in <lambda>
    lambda: _get_explicit_environ_credentials(quota_project_id=quota_project_id),
  File "/home/airflow/.local/lib/python3.9/site-packages/google/auth/_default.py", line 225, in _get_explicit_environ_credentials
    credentials, project_id = load_credentials_from_file(
  File "/home/airflow/.local/lib/python3.9/site-packages/google/auth/_default.py", line 119, in load_credentials_from_file
    raise exceptions.DefaultCredentialsError(
google.auth.exceptions.DefaultCredentialsError: File /.google/credentials/google_credentials.json was not found.
[2025-03-27T07:02:06.847+0000] {taskinstance.py:1401} INFO - Marking task as UP_FOR_RETRY. dag_id=data_ingestion_gcs_dag, task_id=local_to_gcs_task1, execution_date=20250327T065630, start_date=20250327T070206, end_date=20250327T070206
[2025-03-27T07:02:06.867+0000] {standard_task_runner.py:102} ERROR - Failed to execute job 15 for task local_to_gcs_task1 (File /.google/credentials/google_credentials.json was not found.; 1186)
[2025-03-27T07:02:06.902+0000] {local_task_job.py:164} INFO - Task exited with return code 1
[2025-03-27T07:02:06.951+0000] {local_task_job.py:273} INFO - 0 downstream tasks scheduled from follow-on schedule check
